Workbook

Sheet ESF Y ER 2025 LETRA
B1: Anexo II: ESTADOS FINANCIEROS
C3: Histórico | D3: Histórico
B4: ESTADO DE SITUACION FINANCIERA | C4: 46022 | D4: 45657
C5: $ | D5: $
B6: Activo
B7: Caja m/n | C7: ='PT a Caja y DC'!B26 | D7: 50000
B8: Banco | C8: ='PT b Banco'!B17 | D8: 100000
B9: Cheques dif a cobrar | C9: ='PT a Caja y DC'!B27 | D9: 0
B10: Ds x ventas | C10: 4347960 | D10: 3287000
B11: Seguros pagos x adel | C11: ='PT f Seguros'!B10 | D11: 0
B12: Inventarios | C12: ='PT c Stock'!I21 | D12: ='PT c Stock'!I22
B13: PPE | C13: ='PT e PPE'!C21 | D13: ='PT e PPE'!B21
B14: Amort. Acumuladas | C14: ='PT e PPE'!C22 | D14: ='PT e PPE'!B22 | E14: Regularizadora (se expone en negativo)
B15: Cuenta directores | C15: =MAX(0,SUM(C19:C26)+C36-SUM(C7:C14)) | D15: =MAX(0,SUM(D19:D26)+D36-SUM(D7:D14)) | E15: Por diferencia (saldo deudor: directores deben a la empresa)
B16: Total Activo | C16: =SUM(C7:C15) | D16: =SUM(D7:D15)
B18: Pasivo
B19: Ac x compra locales | C19: 270000 | D19: 1710000
B20: Seguros a pagar | C20: ='PT f Seguros'!B5 | D20: 0
B21: Seguros perd a vencer | C21: ='PT f Seguros'!B11 | D21: 0 | E21: Regularizadora (negativa)
B22: Ptamos a pagar | C22: ='PT d Prestamos'!C14 | D22: ='PT d Prestamos'!B14
B23: int a pagar | C23: ='PT d Prestamos'!C16 | D23: ='PT d Prestamos'!B16
B24: int perd a vcer | C24: ='PT d Prestamos'!C17 | D24: ='PT d Prestamos'!B17 | E24: Regularizadora (negativa)
B25: Prestamo a largo plazo | C25: ='PT d Prestamos'!C15 | D25: 250000
B26: Deudas Diversas | C26: 650500 | D26: 500000
B27: Cuenta directores | C27: =MAX(0,SUM(C7:C14)-SUM(C19:C26)-C36) | D27: =MAX(0,SUM(D7:D14)-SUM(D19:D26)-D36) | E27: Por diferencia (0 si el activo excede)
B28: Total Pasivo | C28: =SUM(C19:C27) | D28: =SUM(D19:D27)
B30: Patrimonio
B31: Capital | C31: ='PT g Patrimonio'!B13 | D31: 2600000
B32: Aportes a Capitalizar | C32: ='PT g Patrimonio'!B14 | D32: 400000
B33: Reserva legal | C33: =D33+'PT g Patrimonio'!B4 | D33: 15000
B34: Resultados Acumulados | C34: ='PT g Patrimonio'!B7 | D34: 0 | E34: Remanente no distribuido 30/06/25
B35: Resultados del Ejercicio | C35: =C54 | D35: 800000
B36: Total Patrimonio | C36: =SUM(C31:C35) | D36: =SUM(D31:D35)
B37: Total Pasivo y Patrimonio | C37: =C28+C36 | D37: =D28+D36
B40: ESTADO DE RESULTADOS 2025
B41: Ventas | C41: 4120960
B42: Costo de Ventas | C42: =-'PT c Stock'!I23
B43: Utilidad Bruta | C43: =C41+C42
B44: Amortizaciones | C44: =-'PT e PPE'!F11
B45: Gastos Adm y Ventas | C45: -585663
...

Sheet ECP 2025
A1: ESTADO DE CAMBIOS EN EL PATRIMONIO
G4: Patrimonio
G5: Patrimonio atribuible a los propietarios de la controladora
G6: Capital Integrado | H6: Aportes a capitalizar | I6: Ajustes al patrimonio | J6: Reservas de utilidades | K6: Resultados acumulados | L6: Total
A7: Periodo 01/01/2025 al 31/12/2025
B8: Estado de cambios en el patrimonio [resumen]
C9: Estado de cambios en el patrimonio [partidas]
D10: Saldo inicial de patrimonio | G10: ='ESF Y ER 2025 LETRA'!D31 | H10: ='ESF Y ER 2025 LETRA'!D32 | I10: 0 | J10: ='ESF Y ER 2025 LETRA'!D33 | K10: ='ESF Y ER 2025 LETRA'!D34+'ESF Y ER 2025 LETRA'!D35 | L10: =SUM(G10:K10)
D11: Cambios en el patrimonio [resumen]
E12: Ajuste por cambios en políticas contables | G12: 0 | H12: 0 | I12: 0 | J12: 0 | K12: 0 | L12: =SUM(G12:K12)
E13: Ajuste por corrección de errores | G13: 0 | H13: 0 | I13: 0 | J13: 0 | K13: 0 | L13: =SUM(G13:K13)
E14: Saldo inicial modificado por cambios en políticas contables y corrección de errores | G14: =+G10+G12+G13 | H14: =+H10+H12+H13 | I14: =+I10+I12+I13 | J14: =+J10+J12+J13 | K14: =+K10+K12+K13 | L14: =+L10+L12+L13
E15: Resultado integral [resumen]
F16: Resultado del ejercicio | K16: ='ESF Y ER 2025 LETRA'!C54 | L16: =SUM(G16:K16)
F17: Otro resultado integral | G17: 0 | H17: 0 | I17: 0 | J17: 0 | K17: 0 | L17: =SUM(G17:K17)
F18: Total resultado integral | G18: =+G16+G17 | H18: =+H16+H17 | I18: =+I16+I17 | J18: =+J16+J17 | K18: =+K16+K17 | L18: =+L16+L17
E19: Aportes de capital | G19: ='PT g Patrimonio'!B12 | H19: 200000 | I19: 0 | J19: 0 | K19: 0 | L19: =SUM(G19:K19)
E20: Incrementos (disminuciones) de reserva de utilidades | G20: 0 | H20: 0 | I20: 0 | J20: ='PT g Patrimonio'!B4 | K20: =-'PT g Patrimonio'!B4 | L20: =SUM(G20:K20)
E21: Dividendos reconocidos como distribuciones a los propietarios | G21: 0 | H21: ='PT g Patrimonio'!B5 | I21: 0 | J21: 0 | K21: =-('PT g Patrimonio'!B5+'PT g Patrimonio'!B6) | L21: =SUM(G21:K21)
E22: Incrementos por otras aportaciones de los propietarios, patrimonio | G22: 0 | H22: 0 | I22: 0 | J22: 0 | K22: 0 | L22: =SUM(G22:K22)
E23: Disminuciones por otras distribuciones a los propietarios, patrimonio | G23: 0 | H23: 0 | I23: 0 | J23: 0 | K23: 0 | L23: =SUM(G23:K23)
E24: Incrementos (disminuciones) por otros cambios, patrimonio | G24: ='PT g Patrimonio'!B11 | H24: =-'PT g Patrimonio'!B11 | I24: 0 | J24: 0 | K24: 0 | L24: =SUM(G24:K24)
E25: Incrementos (disminuciones) por transacciones con acciones propias, patrimonio | G25: 0 | H25: 0 | I25: 0 | J25: 0 | K25: 0 | L25: =SUM(G25:K25)
E26: Incrementos (disminuciones) por cambios en las participaciones en la propiedad de subsidiarias que no dan lugar a pérdida de control, patrimonio | G26: 0 | H26: 0 | I26: 0 | J26: 0 | K26: 0 | L26: =SUM(G26:K26)
E27: Incrementos (disminuciones) por transacciones con pagos basados en acciones, patrimonio | G27: 0 | H27: 0 | I27: 0 | J27: 0 | K27: 0 | L27: =SUM(G27:K27)
E28: Total incrementos (disminuciones) en el patrimonio | G28: =SUM(G18:G27) | H28: =SUM(H18:H27) | I28: =SUM(I18:I27) | J28: =SUM(J18:J27) | K28: =SUM(K18:K27) | L28: =SUM(L18:L27)
D29: Saldo final de patrimonio | G29: =+G14+G28 | H29: =+H14+H28 | I29: =+I14+I28 | J29: =+J14+J28 | K29: =+K14+K28 | L29: =+L28+L14
D31: Control vs Estado de Situacion Financiera (debe ser 0)
G32: =G29-'ESF Y ER 2025 LETRA'!C31 | H32: =H29-'ESF Y ER 2025 LETRA'!C32 | J32: =J29-'ESF Y ER 2025 LETRA'!C33 | K32: =K29-'ESF Y ER 2025 LETRA'!C34-'ESF Y ER 2025 LETRA'!C35 | L32: =L29-'ESF Y ER 2025 LETRA'!C36
D34: Notas: (1) Fila 19: aporte en efectivo 31/10 (integra capital) y vehiculo 200.000 (aportes a capitalizar).
D35: (2) Fila 20: reserva legal 5% s/ 800.000. (3) Fila 21: dividendos: 400.000 en acciones (pasan a Aportes a capitalizar) + 200.000 en efectivo.
D36: (4) Fila 24: capitalizacion 03/01/2025 de los aportes a capitalizar 2024 (400.000) - reclasificacion sin efecto en el total.

Sheet EFE 2025
A3: ESTADO DE FLUJO DE EFECTIVO (Método Indirecto)
A5: 1. Fondos relacionados a operaciones
B6: Resultado del ejercicio | F6: ='ESF Y ER 2025 LETRA'!C54
B7: Amortizaciones (no afecta fondos) | F7: =-'ESF Y ER 2025 LETRA'!C44
B8: Resultado por venta de PPE (se refleja en inversiones) | F8: =-'ESF Y ER 2025 LETRA'!C49
G11: =SUM(F6:F9)
B12: Variación de activos y pasivos:
B13: Cheques diferidos a cobrar | F13: =-('ESF Y ER 2025 LETRA'!C9-'ESF Y ER 2025 LETRA'!D9)
B14: Deudores por ventas | F14: =-('ESF Y ER 2025 LETRA'!C10-'ESF Y ER 2025 LETRA'!D10)
B15: Seguros pagos por adelantado | F15: =-('ESF Y ER 2025 LETRA'!C11-'ESF Y ER 2025 LETRA'!D11)
B16: Inventarios | F16: =-('ESF Y ER 2025 LETRA'!C12-'ESF Y ER 2025 LETRA'!D12)
B17: Acreedores por compras locales | F17: ='ESF Y ER 2025 LETRA'!C19-'ESF Y ER 2025 LETRA'!D19
B18: Seguros a pagar (neto de seguros perdidos a vencer) | F18: =('ESF Y ER 2025 LETRA'!C20+'ESF Y ER 2025 LETRA'!C21)-('ESF Y ER 2025 LETRA'!D20+'ESF Y ER 2025 LETRA'!D21)
B19: Deudas diversas | F19: ='ESF Y ER 2025 LETRA'!C26-'ESF Y ER 2025 LETRA'!D26
G20: =+G11+SUM(F13:F19)
A23: 2. Fondos relacionados a inversiones
B24: Cobro por venta de equipos de computacion | F24: ='PT e PPE'!B17
B25: Compra de maquina (600.000; mitad financiada con prestamo) | F25: =-'PT e PPE'!B8
G26: =SUM(F24:F25)
A28: 3. Fondos relacionados a financiamiento
B30: Aporte de capital en efectivo (31/10/2025) | F30: ='PT g Patrimonio'!B12
B31: Dividendos en efectivo pagados | F31: =-'PT g Patrimonio'!B6
B32: Prestamo obtenido (30/06/2025) | F32: 300000
B33: Cancelacion de cuotas de capital prestamo 1 (30/06 y 31/12) | F33: =-('PT d Prestamos'!B7+'PT d Prestamos'!B8)
B34: Cuenta directores (variacion neta) | F34: =('ESF Y ER 2025 LETRA'!D15-'ESF Y ER 2025 LETRA'!D27)-('ESF Y ER 2025 LETRA'!C15-'ESF Y ER 2025 LETRA'!C27)
G36: =SUM(F30:F34)
A38: 4. Variación de disponibilidades | G38: =+G20+G26+G36
A40: 5. Saldo inicial de disponibilidades | B40: Caja + Banco al 31/12/2024 | G40: ='ESF Y ER 2025 LETRA'!D7+'ESF Y ER 2025 LETRA'!D8
A42: 6. Saldo final de disponibilidades | B42: Caja + Banco al 31/12/2025 | G42: ='ESF Y ER 2025 LETRA'!C7+'ESF Y ER 2025 LETRA'!C8
A45: control | G45: =+G40+G38-G42
A47: Transacciones sin movimiento de efectivo (no incluidas): aporte en especie (vehiculo) 200.000; dividendos en acciones 400.000; capitalizacion de aportes 400.000.
A48: Disponibilidades = Caja + Banco. Los cheques diferidos a cobrar (vto 31/03/26) no se consideran efectivo. Intereses pagados (150.000) estan dentro del resultado.

Sheet PT a Caja y DC
A1: a) Arqueo de caja y diferencia de cambio
A2: Todo en moneda nacional. Solo se actualizan Caja, Faltante/Sobrante, Cheques diferidos a cobrar y D/C.
A4: Saldo contable de Caja MN antes del arqueo | B4: 42500
A6: Comprobantes en poder del cajero (aun no registrados) | B6: Efecto en Caja | D6: Criterio
A7: e-Boleta de venta contado | B7: 34000 | D7: Cobro en efectivo: aumenta Caja
A8: e-Factura de venta a credito | B8: 0 | D8: No afecta Caja (Ds x ventas)
A9: Recibo por pago contado emitido por proveedor | B9: -1100 | D9: Pago en efectivo: disminuye Caja
A10: Recibo por cobranza con cheque del dia | B10: 43000 | D10: Cheque del dia = valor en Caja
A11: Recibo por pago a proveedor en efectivo | B11: -42500 | D11: Pago en efectivo: disminuye Caja
A12: e-Facturas por compras a credito | B12: 0 | D12: No afecta Caja (Ac x compra)
A13: Recibo de pago a proveedor con cheque Nro 5 | B13: 0 | D13: Sale de Banco (ya en el mayor bancario)
A14: Cheque diferido Nro 98 (vto 31/03/2026) | B14: 0 | D14: Ya registrado: Cheques dif. a cobrar 2.300
A15: Saldo contable ajustado por comprobantes | B15: =B4+SUM(B7:B14)
A17: Valores contados en caja (arqueo fisico)
A18: Monedas y billetes | B18: 25800
A19: Cheque del dia | B19: 43000
A20: Cheque diferido Nro 321 (vto 15/12/2025: ya vencido = valor al dia) | B20: 5500 | D20: A 31/12/25 ya es exigible: se trata como Caja
A21: Total valores en caja | B21: =SUM(B18:B20)
A23: Diferencia (valores - saldo ajustado) <0 = FALTANTE | B23: =B21-B15
A24: Faltante de caja (perdida, a Estado de Resultados) | B24: =B23
A26: Caja MN al 31/12/2025 | B26: =B15+B23
A27: Cheques diferidos a cobrar al 31/12/2025 (solo el Nro 98) | B27: 2300
A29: Diferencia de cambio (unico movimiento en USD)
A30: USD comprados 30/06/2025 | B30: 10000
A31: T/C 30/06/2025 | B31: 39.548
A32: T/C 30/09/2025 | B32: 39.845
A33: Costo de compra ($) | B33: =B30*B31
A34: Importe de venta ($) | B34: =B30*B32
A35: Diferencia de cambio GANADA | B35: =B34-B33

Sheet PT b Banco
A1: b) Conciliacion bancaria al 31/12/2025
A2: Banco cuenta corriente moneda nacional
A4: Saldo del mayor (empresa) al 31/12/25 | B4: =258000+23000-1500+15000-10000-1100+8900-550 | D4: Saldo estado de cuenta (banco) al 31/12/25 | E4: =154000+188000-49000+23000-14000+1500-10000-550-2500
A5: Ajustes a la empresa (partidas que el banco conoce y la empresa no) | D5: Ajustes al banco (partidas que la empresa conoce y el banco no)
A6: Costo mantenimiento cuenta corriente (nota de debito) | B6: -2500 | D6: Deposito en transito: boleta Nro 768 (28/12) | E6: 8900
A7: Error de la empresa: transf. recibida Nro 534 registrada por 15.000 y el banco acredito 1.500 | B7: =-(15000-1500) | D7: Cheque Nro 4 pendiente de cobro (proveedor X) | E7: -1500
D8: Cheque Nro 2 pendiente de cobro (conciliacion de nov.) | E8: -21000
A9: Saldo conciliado - empresa | B9: =B4+B6+B7 | D9: Transferencia Nro 45 (proveedor AA) no acreditada aun | E9: -1100
D10: Saldo conciliado - banco | E10: =E4+SUM(E6:E9)
A12: Control (deben coincidir) | B12: =B9-E10
A14: Partidas de noviembre ya resueltas: deposito 501, cheque 1 y transferencia 76 se acreditaron/debitaron en diciembre. Cheque 2 sigue pendiente.
A15: Supuesto: ante una diferencia empresa-banco en un importe, se presume correcto el estado de cuenta (transposicion 15.000 vs 1.500).
A17: Banco cuenta corriente MN al 31/12/2025 | B17: =B9

Sheet PT c Stock
A1: c) Planilla de stock - FIFO (PEPS), permanencia de inventario
A4: Fecha | B4: Concepto | C4: Ent uds | D4: Ent Cunit | E4: Ent total | F4: Sal uds | G4: Sal total | H4: Saldo uds | I4: Saldo total | J4: Detalle de capas (FIFO)
A5: SI | H5: 5 | I5: 50000 | J5: 5 @ 10.000
A6: 08-ene | B6: VENTA | F6: 5 | G6: 50000 | H6: =H5+N(C6)-N(F6) | I6: =I5+N(E6)-N(G6) | J6: sale 5 @ 10.000 -> 0
A7: 09-ene | B7: COMPRA | C7: 40 | D7: 11000 | E7: 440000 | H7: =H6+N(C7)-N(F7) | I7: =I6+N(E7)-N(G7) | J7: 40 @ 11.000
A8: 14-feb | B8: VENTA | F8: 15 | G8: 165000 | H8: =H7+N(C8)-N(F8) | I8: =I7+N(E8)-N(G8) | J8: sale 15 @ 11.000 -> 25 @ 11.000
A9: 15-mar | B9: COMPRA | C9: 20 | D9: 12000 | E9: 240000 | H9: =H8+N(C9)-N(F9) | I9: =I8+N(E9)-N(G9) | J9: 25 @ 11.000 + 20 @ 12.000
A10: 31-mar | B10: VENTA | F10: 5 | G10: 55000 | H10: =H9+N(C10)-N(F10) | I10: =I9+N(E10)-N(G10) | J10: sale 5 @ 11.000 -> 20 @ 11.000 + 20 @ 12.000
A11: 30-abr | B11: VENTA | F11: 5 | G11: 55000 | H11: =H10+N(C11)-N(F11) | I11: =I10+N(E11)-N(G11) | J11: sale 5 @ 11.000 -> 15 @ 11.000 + 20 @ 12.000
A12: 30-jun | B12: VENTA | F12: 5 | G12: 55000 | H12: =H11+N(C12)-N(F12) | I12: =I11+N(E12)-N(G12) | J12: sale 5 @ 11.000 -> 10 @ 11.000 + 20 @ 12.000
A13: 31-dic | B13: VENTA | F13: 10 | G13: 110000 | H13: =H12+N(C13)-N(F13) | I13: =I12+N(E13)-N(G13) | J13: sale 10 @ 11.000 -> 20 @ 12.000
A14: 31-dic | B14: COMPRA | C14: 20 | D14: 15000 | E14: 300000 | H14: =H13+N(C14)-N(F14) | I14: =I13+N(E14)-N(G14) | J14: 20 @ 12.000 + 20 @ 15.000
A16: Saldo teorico al 31/12 | H16: =H14 | I16: =I14
A17: Recuento fisico (uds) | H17: 39
A18: Diferencia de stock (uds) faltante | H18: =H16-H17
A19: Valuacion de la diferencia: 1 ud. de la capa mas antigua (FIFO) @ 12.000 | I19: =H18*12000
A21: Inventario final (19 @ 12.000 + 20 @ 15.000) | I21: =I16-I19
A22: Inventario inicial | I22: =I5
A23: Costo de ventas 2025 (suma de salidas) | I23: =SUM(G5:G14)
A24: Control: inv. inicial + compras - costo ventas - dif. stock | I24: =I22+SUM(E5:E14)-I23-I19-I21
A26: Unidades vendidas 2025 | H26: =SUM(F5:F14)

Sheet PT d Prestamos
A1: d) Prestamos, intereses a pagar / perdidos / perdidos a vencer
A3: Prestamo 1: $1.000.000 al 01/07/2024, 24% anual lineal sobre saldos = 12% semestral, 4 cuotas semestrales de capital 250.000
A4: Vencimiento | B4: Capital | C4: Interes | D4: Cuota | E4: Saldo capital luego
A5: Saldo inicial 01/07/2024 | E5: 1000000
A6: 31/12/2024 | B6: 250000 | C6: =E5*0.24/2 | D6: =B6+C6 | E6: =E5-B6
A7: 30/06/2025 | B7: 250000 | C7: =E6*0.24/2 | D7: =B7+C7 | E7: =E6-B7
A8: 31/12/2025 | B8: 250000 | C8: =E7*0.24/2 | D8: =B8+C8 | E8: =E7-B8
A9: 30/06/2026 | B9: 250000 | C9: =E8*0.24/2 | D9: =B9+C9 | E9: =E8-B9
A10: Total | B10: =SUM(B6:B9) | C10: =SUM(C6:C9) | D10: =SUM(D6:D9)
A12: Saldos (metodo bruto: Int. a pagar = intereses nominales futuros; Int. perdidos a vencer = mismo importe, regularizadora)
B13: 31/12/2024 | C13: 31/12/2025
A14: Prestamos a pagar (capital exigible en 12 meses) | B14: =B7+B8 | C14: =B9
A15: Prestamo a largo plazo | B15: =B9 | C15: 300000 | F15: 2024: cuota 30/06/26 (dato ESF=250.000). 2025: Prestamo 2 sin interes, vto 30/06/27
A16: Intereses a pagar (nominal, cuotas futuras) | B16: =C7+C8+C9 | C16: =C9
A17: Intereses perdidos a vencer (regularizadora) | B17: =-B16 | C17: =-C16
A19: Intereses perdidos 2025 (devengados) | B19: =C7+C8 | F19: 01-06/2025: 750.000 x 12% + 07-12/2025: 500.000 x 12%
A20: Intereses pagados 2025 (cuotas 30/06 y 31/12) | B20: =C7+C8
A22: Prestamo 2: $300.000 al 30/06/2025, sin interes, cuota unica 30/06/2027 (financia 50% de la maquina)

Sheet PT e PPE
A1: e) Propiedad, planta y equipo
A4: Bien | B4: Costo | C4: Vida util (a) | D4: Amort. anual | E4: Amort. ac. 01/01/25 | F4: Amort. 2025 | G4: Observaciones
A5: Inmueble - edificio (80%) | B5: =2000000*0.8 | C5: 50 | D5: =B5/C5 | E5: =D5*6 | F5: =D5 | G5: Aporte inicial 2.000.000 (01/01/2019). Amortiza desde incorporacion: 6 anios a 01/01/25
A6: Inmueble - terreno (20%, no se amortiza) | B6: =2000000*0.2 | E6: 0 | F6: 0
A7: Equipos de computacion | B7: 100000 | C7: 5 | D7: =B7/C7 | E7: =D7*6/12 | F7: =D7*9/12 | G7: Comprados 30/06/24 (6 meses en 2024). Vendidos 30/09/25 (9 meses en 2025)
A8: Maquina (30/06/2025) | B8: =300000*2 | C8: 10 | D8: =B8/C8 | E8: 0 | F8: =D8*6/12 | G8: Mitad efectivo + mitad prestamo 300.000 => precio 600.000
A9: Vehiculo (aporte en especie 31/12/2025) | B9: 200000 | E9: 0 | F9: 0 | G9: Incorporado el ultimo dia: sin amortizacion en 2025
A11: Amortizaciones 2025 (Estado de Resultados) | F11: =F5+F7+F8+F9
A13: Baja de equipos de computacion 30/09/2025
A14: Costo | B14: =B7
A15: Amortizacion acumulada a la baja | B15: =E7+F7
A16: Valor neto contable | B16: =B14-B15
A17: Precio de venta (3 cuotas de 50.000 cobradas) | B17: 150000
A18: Resultado por venta de PPE (ganancia) | B18: =B17-B16
A20: Saldos | B20: 31/12/2024 | C20: 31/12/2025
A21: PPE (costo) | B21: =B5+B6+B7 | C21: =B5+B6+B8+B9
A22: Amortizaciones acumuladas | B22: =-(E5+E7) | C22: =-(E5+F5+F8)
A24: Sensibilidad: si el inmueble se amortizara desde 2015 (10 anios) la amort. acumulada sube 128.000; el resultado 2025 no cambia.

Sheet PT f Seguros
A1: f) Seguro contra incendio del inmueble
A3: Prima total | B3: 48000
A4: Pagado al contratar | B4: 18000
A5: Saldo impago 31/12/2025 = Seguros a pagar | B5: =B3-B4
A6: Vigencia (meses) / meses transcurridos al 31/12/25 | B6: 12 | C6: 5
A8: Seguros (gasto 2025) = 48.000 x 5/12 | B8: =B3*C6/B6
A9: Diferido a 31/12 (7 meses) | B9: =B3-B8
A10: Parte pagada (18.000): Seguros pagos x adelantado | B10: =ROUND(B4*(1-C6/B6),0)
A11: Parte financiada (30.000): Seguros perdidos a vencer (regularizadora del pasivo) | B11: =-ROUND(B5*(1-C6/B6),0)
A12: Control: gasto + diferido = prima | B12: =B8+B10-B11-B3
A14: Criterio: la prima se reparte en proporcion a lo pagado y a lo financiado (mismo tratamiento que los intereses a vencer).

Sheet PT g Patrimonio
A1: g) Cuentas patrimoniales y distribucion de resultados
A3: Resultado 2024 a distribuir (Asamblea 30/06/2025) | B3: 800000
A4: Reserva legal = 5% de las ganancias liquidas del ejercicio (art. 93 Ley 16.060) | B4: =B3*0.05 | C4: Tope 20% del capital: 15.000+40.000 << 520.000
A5: Dividendos en acciones (a capitalizar) | B5: 400000
A6: Dividendos en efectivo (pagados en 2025) | B6: 200000
A7: Remanente que queda en Resultados acumulados | B7: =B3-B4-B5-B6
A9: Capital (integrado) y aportes a capitalizar
A10: Capital integrado 31/12/2024 | B10: 2600000
A11: Aportes a capitalizar 31/12/2024 | B11: 400000
A12: Aporte en efectivo 31/10/2025 | B12: 800000 | C12: Completa la ampliacion 2.6M->3.8M: 400.000 + 800.000 = 1.200.000
A13: Capital integrado 31/12/2025 (= capital contractual) | B13: =B10+B11+B12
A14: Aportes a capitalizar 31/12/2025 = div. en acciones 400.000 + vehiculo 200.000 | B14: =B5+200000
A16: Pedido 2 b) - ampliacion minima del capital contractual
A17: Capital contractual vigente | B17: 3800000
A18: Capital integrado + aportes a capitalizar | B18: =B13+B14
A19: Ampliacion minima requerida | B19: =B18-B17
A21: Pedido 2 a) - hipotesis alternativa (distribuir la totalidad de los resultados)
A22: Resultados a distribuir | B22: =B3
A23: Reserva legal 5% | B23: =B22*0.05
A24: Remanente | B24: =B22-B23
A25: 50% dividendos en acciones | B25: =B24*0.5
A26: 50% dividendos en efectivo | B26: =B24*0.5

Sheet Asientos
A1: Libro diario: arqueo, conciliacion bancaria y pedido 2 a)
A3: Fecha | B3: Cuenta | C3: Debe | D3: Haber | E3: Glosa
A4: 31/12/2025 | B4: Caja | C4: 34000 | E4: Boleta de venta contado no registrada
B5: Ventas | D5: 34000
A7: 31/12/2025 | B7: Caja | C7: 43000 | E7: Cobranza con cheque del dia (recibo)
B8: Deudores por ventas | D8: 43000
A10: 31/12/2025 | B10: Acreedores por compras locales | C10: 1100 | E10: Pago contado a proveedor
B11: Caja | D11: 1100
A13: 31/12/2025 | B13: Acreedores por compras locales | C13: 42500 | E13: Pago a proveedor en efectivo
B14: Caja | D14: 42500
A16: 31/12/2025 | B16: Faltante de caja | C16: 1600 | E16: Faltante determinado en el arqueo (75.900 contable vs 74.300 contado)
B17: Caja | D17: 1600
A19: 31/12/2025 | B19: Gastos de administracion y ventas | C19: 2500 | E19: Costo mantenimiento cuenta corriente (extracto)
B20: Banco cuenta corriente MN | D20: 2500
A22: 31/12/2025 | B22: Deudores por ventas (contrapartida original) | C22: 13500 | E22: Correccion transf. Nro 534: registrada 15.000, acreditada 1.500
B23: Banco cuenta corriente MN | D23: 13500
A25: 30/06/2025 | B25: Resultados acumulados (Resultado ej. 2024) | C25: 800000 | E25: Pedido 2 a) Distribucion segun hipotesis alternativa
B26: Reserva legal | D26: 40000
B27: Aportes a capitalizar (dividendos en acciones) | D27: 380000
B28: Dividendos a pagar | D28: 380000
A30: 30/06/2025 | B30: Dividendos a pagar | C30: 380000 | E30: Pedido 2 a) Pago de dividendos en efectivo
B31: Caja | D31: 380000
B33: Nota: las contrapartidas se muestran solo para cuadrar el asiento; las demas cuentas ya figuran con su saldo final en el Anexo II.

Sheet Pedido 3 Indicadores
A1: Pedido 3 - Indicadores de apoyo al analisis de inversion
B3: 2025 | C3: 2024 | D3: Lectura
A4: Activo corriente | B4: =SUM('ESF Y ER 2025 LETRA'!C7:'ESF Y ER 2025 LETRA'!C12) | C4: =SUM('ESF Y ER 2025 LETRA'!D7:'ESF Y ER 2025 LETRA'!D12)
A5: Pasivo corriente (neto de regularizadoras) | B5: ='ESF Y ER 2025 LETRA'!C19+'ESF Y ER 2025 LETRA'!C20+'ESF Y ER 2025 LETRA'!C21+'ESF Y ER 2025 LETRA'!C22+'ESF Y ER 2025 LETRA'!C23+'ESF Y ER 2025 LETRA'!C24+'ESF Y ER 2025 LETRA'!C26 | C5: ='ESF Y ER 2025 LETRA'!D19+'ESF Y ER 2025 LETRA'!D22+'ESF Y ER 2025 LETRA'!D23+'ESF Y ER 2025 LETRA'!D24+'ESF Y ER 2025 LETRA'!D26 | D5: Se considera corriente el pasivo exigible en 12 meses
A6: Liquidez corriente | B6: =B4/B5 | C6: =C4/C5 | D6: Alta, pero 83% del AC son cuentas por cobrar
A7: Liquidez inmediata (Caja + Banco / P. corriente) | B7: =('ESF Y ER 2025 LETRA'!C7+'ESF Y ER 2025 LETRA'!C8)/B5 | C7: =('ESF Y ER 2025 LETRA'!D7+'ESF Y ER 2025 LETRA'!D8)/C5 | D7: Baja: la caja no cubre el pasivo corriente
A8: Endeudamiento (Pasivo / Patrimonio) | B8: ='ESF Y ER 2025 LETRA'!C28/'ESF Y ER 2025 LETRA'!C36 | C8: ='ESF Y ER 2025 LETRA'!D28/'ESF Y ER 2025 LETRA'!D36 | D8: Bajo apalancamiento
A9: Margen bruto | B9: ='ESF Y ER 2025 LETRA'!C43/'ESF Y ER 2025 LETRA'!C41 | D9: Muy alto: revisar precio de venta vs. costo unitario
A10: Margen neto | B10: ='ESF Y ER 2025 LETRA'!C54/'ESF Y ER 2025 LETRA'!C41
A11: ROE (resultado / patrimonio final) | B11: ='ESF Y ER 2025 LETRA'!C54/'ESF Y ER 2025 LETRA'!C36 | C11: ='ESF Y ER 2025 LETRA'!D35/'ESF Y ER 2025 LETRA'!D36
A12: Plazo de cobranza (dias) = Ds x ventas / Ventas x 365 | B12: ='ESF Y ER 2025 LETRA'!C10/'ESF Y ER 2025 LETRA'!C41*365 | D12: Deudores por ventas superan las ventas anuales
A13: Dias de inventario = Inventario / Costo de ventas x 365 | B13: ='ESF Y ER 2025 LETRA'!C12/-'ESF Y ER 2025 LETRA'!C42*365 | D13: Inventario se multiplico por ~10
A14: Flujo de efectivo de operaciones | B14: ='EFE 2025'!G20 | D14: Casi nulo frente a un resultado de 2,86 millones
A15: Flujo operativo / Resultado del ejercicio | B15: ='EFE 2025'!G20/'ESF Y ER 2025 LETRA'!C54 | D15: Baja conversion de resultados en caja
A16: Cuenta directores / Activo total | B16: ='ESF Y ER 2025 LETRA'!C15/'ESF Y ER 2025 LETRA'!C16 | C16: ='ESF Y ER 2025 LETRA'!D15/'ESF Y ER 2025 LETRA'!D16 | D16: Financiamiento a partes relacionadas
A19: Unidades vendidas por trimestre (planilla de stock)
A20: T1 (ene-mar) | B20: 25
A21: T2 (abr-jun) | B21: 10
A22: T3 (jul-sep) | B22: 0
A23: T4 (oct-dic) | B23: 10
A25: Costo unitario de compra: 10.000 (SI) -> 11.000 (ene) -> 12.000 (mar) -> 15.000 (dic): +50%.
